<?xml version="1.0" ?>
<!-- Generated using onshape-to-robot -->
<!-- Onshape https://cad.onshape.com/documents/8728c7fdb0e0b3c78180e1fb/w/70d590d987c43934e5d14436/e/c77dbd6d3fbd22e2e0636f89 -->
<mujoco model="openarm_right">
  <compiler angle="radian" meshdir="assets" autolimits="true"/>
  <default>
    <default class="openarm_right">
      <joint frictionloss="0.1" armature="0.005"/>
      <position kp="50" dampratio="1"/>
      <default class="visual">
        <geom type="mesh" contype="0" conaffinity="0" group="2"/>
      </default>
      <default class="collision">
        <geom group="3"/>
      </default>
    </default>
  </default>
  <worldbody>
    <!-- Link hfsb6_6060_750_1_step -->
    <body name="hfsb6_6060_750_1_step" pos="0 0 0" quat="1 0 0 0" childclass="openarm_right">
      <inertial pos="0 0 0" mass="1e-09" fullinertia="1e-09 1e-09 1e-09 0 0 0"/>
      <!-- Part j1_b_2_step -->
      <geom type="mesh" class="visual" pos="1e-12 3e-12 -0.008" quat="1 0 -0 -0" mesh="j1_b_2_step" material="j1_b_2_step_material"/>
      <geom type="mesh" class="collision" pos="1e-12 3e-12 -0.008" quat="1 0 -0 -0" mesh="j1_b_2_step" material="j1_b_2_step_material"/>
      <!-- Part hfsb6_6060_750_1_step -->
      <geom type="mesh" class="visual" pos="-4e-12 -3e-12 0.758" quat="0 -0.707107 0.707107 -0" mesh="hfsb6_6060_750_1_step" material="hfsb6_6060_750_1_step_material"/>
      <geom type="mesh" class="collision" pos="-4e-12 -3e-12 0.758" quat="0 -0.707107 0.707107 -0" mesh="hfsb6_6060_750_1_step" material="hfsb6_6060_750_1_step_material"/>
      <!-- Part dm_j8009p_2_step -->
      <geom type="mesh" class="visual" pos="1e-12 3e-12 -0.008" quat="1 0 -0 -0" mesh="dm_j8009p_2_step" material="dm_j8009p_2_step_material"/>
      <geom type="mesh" class="collision" pos="1e-12 3e-12 -0.008" quat="1 0 -0 -0" mesh="dm_j8009p_2_step" material="dm_j8009p_2_step_material"/>
      <!-- Part j1_a_1_step -->
      <geom type="mesh" class="visual" pos="1e-12 3e-12 -0.008" quat="1 0 -0 -0" mesh="j1_a_1_step" material="j1_a_1_step_material"/>
      <geom type="mesh" class="collision" pos="1e-12 3e-12 -0.008" quat="1 0 -0 -0" mesh="j1_a_1_step" material="j1_a_1_step_material"/>
      <!-- Link dm_j8009p_2_step_1 -->
      <body name="dm_j8009p_2_step_1" pos="-0 -0.0925 0.689" quat="0.707107 -0.707107 0 -0">
        <!-- Joint from hfsb6_6060_750_1_step to dm_j8009p_2_step_1 -->
        <joint axis="0 0 1" name="r_arm_pitch" type="hinge" range="-2.9999940913754926 0.9999863949301521"/>
        <inertial pos="0 0 0" mass="1e-09" fullinertia="1e-09 1e-09 1e-09 0 0 0"/>
        <!-- Part dm_j8009p_2_step_1 -->
        <geom type="mesh" class="visual" pos="1e-12 0.697 0.0925" quat="0.707107 0.707107 -0 0" mesh="dm_j8009p_2_step_1" material="dm_j8009p_2_step_1_material"/>
        <geom type="mesh" class="collision" pos="1e-12 0.697 0.0925" quat="0.707107 0.707107 -0 0" mesh="dm_j8009p_2_step_1" material="dm_j8009p_2_step_1_material"/>
        <!-- Part j1_e_1_step -->
        <geom type="mesh" class="visual" pos="1e-12 0.697 0.0925" quat="0.707107 0.707107 -0 0" mesh="j1_e_1_step" material="j1_e_1_step_material"/>
        <geom type="mesh" class="collision" pos="1e-12 0.697 0.0925" quat="0.707107 0.707107 -0 0" mesh="j1_e_1_step" material="j1_e_1_step_material"/>
        <!-- Part j1_d_1_step -->
        <geom type="mesh" class="visual" pos="1e-12 0.697 0.0925" quat="0.707107 0.707107 -0 0" mesh="j1_d_1_step" material="j1_d_1_step_material"/>
        <geom type="mesh" class="collision" pos="1e-12 0.697 0.0925" quat="0.707107 0.707107 -0 0" mesh="j1_d_1_step" material="j1_d_1_step_material"/>
        <!-- Part j1_c_1_step -->
        <geom type="mesh" class="visual" pos="1e-12 0.697 0.0925" quat="0.707107 0.707107 -0 0" mesh="j1_c_1_step" material="j1_c_1_step_material"/>
        <geom type="mesh" class="collision" pos="1e-12 0.697 0.0925" quat="0.707107 0.707107 -0 0" mesh="j1_c_1_step" material="j1_c_1_step_material"/>
        <!-- Link j2_b_2_step -->
        <body name="j2_b_2_step" pos="-0.0301 0 -0.06" quat="0 -0.707107 0 -0.707107">
          <!-- Joint from dm_j8009p_2_step_1 to j2_b_2_step -->
          <joint axis="0 0 1" name="r_arm_roll" type="hinge" range="-3.3161255787892263 0.17453292519943295"/>
          <inertial pos="0 0 0" mass="1e-09" fullinertia="1e-09 1e-09 1e-09 0 0 0"/>
          <!-- Part j2_a_1_step -->
          <geom type="mesh" class="visual" pos="0.1525 -0.697 0.0301" quat="0.5 -0.5 -0.5 -0.5" mesh="j2_a_1_step" material="j2_a_1_step_material"/>
          <geom type="mesh" class="collision" pos="0.1525 -0.697 0.0301" quat="0.5 -0.5 -0.5 -0.5" mesh="j2_a_1_step" material="j2_a_1_step_material"/>
          <!-- Part j2_c_2_step -->
          <geom type="mesh" class="visual" pos="0.1525 -0.697 0.0301" quat="0.5 -0.5 -0.5 -0.5" mesh="j2_c_2_step" material="j2_c_2_step_material"/>
          <geom type="mesh" class="collision" pos="0.1525 -0.697 0.0301" quat="0.5 -0.5 -0.5 -0.5" mesh="j2_c_2_step" material="j2_c_2_step_material"/>
          <!-- Part j2_b_2_step -->
          <geom type="mesh" class="visual" pos="0.1525 -0.697 0.0301" quat="0.5 -0.5 -0.5 -0.5" mesh="j2_b_2_step" material="j2_b_2_step_material"/>
          <geom type="mesh" class="collision" pos="0.1525 -0.697 0.0301" quat="0.5 -0.5 -0.5 -0.5" mesh="j2_b_2_step" material="j2_b_2_step_material"/>
          <!-- Link dm_j4340_2_step -->
          <body name="dm_j4340_2_step" pos="-0 -0.06625 0.0301" quat="0.5 -0.5 -0.5 -0.5">
            <!-- Joint from j2_b_2_step to dm_j4340_2_step -->
            <joint axis="0 0 1" name="r_arm_yaw" type="hinge" range="-1.5707963267948948 1.5707963267948983"/>
            <inertial pos="0 0 0" mass="1e-09" fullinertia="1e-09 1e-09 1e-09 0 0 0"/>
            <!-- Part dm_j4340p_2_step -->
            <geom type="mesh" class="visual" pos="1e-12 0.1525 -0.63075" quat="1 0 -0 -0" mesh="dm_j4340p_2_step" material="dm_j4340p_2_step_material"/>
            <geom type="mesh" class="collision" pos="1e-12 0.1525 -0.63075" quat="1 0 -0 -0" mesh="dm_j4340p_2_step" material="dm_j4340p_2_step_material"/>
            <!-- Part fl6803zz_2_step -->
            <geom type="mesh" class="visual" pos="1e-12 0.1525 -0.63075" quat="1 0 -0 -0" mesh="fl6803zz_2_step" material="fl6803zz_2_step_material"/>
            <geom type="mesh" class="collision" pos="1e-12 0.1525 -0.63075" quat="1 0 -0 -0" mesh="fl6803zz_2_step" material="fl6803zz_2_step_material"/>
            <!-- Part j4_a_2_step -->
            <geom type="mesh" class="visual" pos="1e-12 0.1525 -0.63075" quat="1 0 -0 -0" mesh="j4_a_2_step" material="j4_a_2_step_material"/>
            <geom type="mesh" class="collision" pos="1e-12 0.1525 -0.63075" quat="1 0 -0 -0" mesh="j4_a_2_step" material="j4_a_2_step_material"/>
            <!-- Part dm_j4340_2_step -->
            <geom type="mesh" class="visual" pos="1e-12 0.1525 -0.63075" quat="1 0 -0 -0" mesh="dm_j4340_2_step" material="dm_j4340_2_step_material"/>
            <geom type="mesh" class="collision" pos="1e-12 0.1525 -0.63075" quat="1 0 -0 -0" mesh="dm_j4340_2_step" material="dm_j4340_2_step_material"/>
            <!-- Part j4_b_2_step -->
            <geom type="mesh" class="visual" pos="1e-12 0.1525 -0.63075" quat="1 0 -0 -0" mesh="j4_b_2_step" material="j4_b_2_step_material"/>
            <geom type="mesh" class="collision" pos="1e-12 0.1525 -0.63075" quat="1 0 -0 -0" mesh="j4_b_2_step" material="j4_b_2_step_material"/>
            <!-- Link dm_j4310_1_2_step -->
            <body name="dm_j4310_1_2_step" pos="0 -0.03155 -0.15375" quat="0.707107 -0.707107 -0 -0">
              <!-- Joint from dm_j4340_2_step to dm_j4310_1_2_step -->
              <joint axis="0 0 1" name="r_elbow" type="hinge" range="-2.4434609527920603 8.881784197001252e-16"/>
              <inertial pos="0 0 0" mass="1e-09" fullinertia="1e-09 1e-09 1e-09 0 0 0"/>
              <!-- Part j4_d_2_step -->
              <geom type="mesh" class="visual" pos="1e-12 0.477 0.18405" quat="0.707107 0.707107 -0 0" mesh="j4_d_2_step" material="j4_d_2_step_material"/>
              <geom type="mesh" class="collision" pos="1e-12 0.477 0.18405" quat="0.707107 0.707107 -0 0" mesh="j4_d_2_step" material="j4_d_2_step_material"/>
              <!-- Part j4_c_2_step -->
              <geom type="mesh" class="visual" pos="1e-12 0.477 0.18405" quat="0.707107 0.707107 -0 0" mesh="j4_c_2_step" material="j4_c_2_step_material"/>
              <geom type="mesh" class="collision" pos="1e-12 0.477 0.18405" quat="0.707107 0.707107 -0 0" mesh="j4_c_2_step" material="j4_c_2_step_material"/>
              <!-- Part dm_j4310_1_2_step -->
              <geom type="mesh" class="visual" pos="1e-12 0.477 0.18405" quat="0.707107 0.707107 -0 0" mesh="dm_j4310_1_2_step" material="dm_j4310_1_2_step_material"/>
              <geom type="mesh" class="collision" pos="1e-12 0.477 0.18405" quat="0.707107 0.707107 -0 0" mesh="dm_j4310_1_2_step" material="dm_j4310_1_2_step_material"/>
              <!-- Part j4_e_2_step -->
              <geom type="mesh" class="visual" pos="1e-12 0.477 0.18405" quat="0.707107 0.707107 -0 0" mesh="j4_e_2_step" material="j4_e_2_step_material"/>
              <geom type="mesh" class="collision" pos="1e-12 0.477 0.18405" quat="0.707107 0.707107 -0 0" mesh="j4_e_2_step" material="j4_e_2_step_material"/>
              <!-- Link j6_a_3_step -->
              <body name="j6_a_3_step" pos="-0 0.0955 0.0315" quat="0.707107 0.707107 0 0">
                <!-- Joint from dm_j4310_1_2_step to j6_a_3_step -->
                <joint axis="0 0 1" name="r_wrist_yaw" type="hinge" range="-1.5707963267948957 1.5707963267948974"/>
                <inertial pos="0 0 0" mass="1e-09" fullinertia="1e-09 1e-09 1e-09 0 0 0"/>
                <!-- Part j6_d_3_step -->
                <geom type="mesh" class="visual" pos="1e-12 0.15255 -0.3815" quat="1 0 -0 0" mesh="j6_d_3_step" material="j6_d_3_step_material"/>
                <geom type="mesh" class="collision" pos="1e-12 0.15255 -0.3815" quat="1 0 -0 0" mesh="j6_d_3_step" material="j6_d_3_step_material"/>
                <!-- Part dm_j4310_1_2_step_1 -->
                <geom type="mesh" class="visual" pos="1e-12 0.15255 -0.3815" quat="1 0 -0 0" mesh="dm_j4310_1_2_step_1" material="dm_j4310_1_2_step_1_material"/>
                <geom type="mesh" class="collision" pos="1e-12 0.15255 -0.3815" quat="1 0 -0 0" mesh="dm_j4310_1_2_step_1" material="dm_j4310_1_2_step_1_material"/>
                <!-- Part j6_b_3_step -->
                <geom type="mesh" class="visual" pos="1e-12 0.15255 -0.3815" quat="1 0 -0 -0" mesh="j6_b_3_step" material="j6_b_3_step_material"/>
                <geom type="mesh" class="collision" pos="1e-12 0.15255 -0.3815" quat="1 0 -0 -0" mesh="j6_b_3_step" material="j6_b_3_step_material"/>
                <!-- Part j5_a_3_step -->
                <geom type="mesh" class="visual" pos="1e-12 0.15255 -0.3815" quat="1 -0 -0 0" mesh="j5_a_3_step" material="j5_a_3_step_material"/>
                <geom type="mesh" class="collision" pos="1e-12 0.15255 -0.3815" quat="1 -0 -0 0" mesh="j5_a_3_step" material="j5_a_3_step_material"/>
                <!-- Part j6_a_3_step -->
                <geom type="mesh" class="visual" pos="1e-12 0.15255 -0.3815" quat="1 0 -0 0" mesh="j6_a_3_step" material="j6_a_3_step_material"/>
                <geom type="mesh" class="collision" pos="1e-12 0.15255 -0.3815" quat="1 0 -0 0" mesh="j6_a_3_step" material="j6_a_3_step_material"/>
                <!-- Part j6_c_right_2_step -->
                <geom type="mesh" class="visual" pos="1e-12 0.15255 -0.3815" quat="1 0 -0 -0" mesh="j6_c_right_2_step" material="j6_c_right_2_step_material"/>
                <geom type="mesh" class="collision" pos="1e-12 0.15255 -0.3815" quat="1 0 -0 -0" mesh="j6_c_right_2_step" material="j6_c_right_2_step_material"/>
                <!-- Link j7_e_2_step -->
                <body name="j7_e_2_step" pos="0.0172 -0 -0.0455" quat="0.5 -0.5 -0.5 0.5">
                  <!-- Joint from j6_a_3_step to j7_e_2_step -->
                  <joint axis="0 0 1" name="r_wrist_roll" type="hinge" range="-0.785398 0.785398"/>
                  <inertial pos="0 0 0" mass="1e-09" fullinertia="1e-09 1e-09 1e-09 0 0 0"/>
                  <!-- Part j7_e_2_step -->
                  <geom type="mesh" class="visual" pos="0.15255 0.336 0.0172" quat="0.5 0.5 0.5 -0.5" mesh="j7_e_2_step" material="j7_e_2_step_material"/>
                  <geom type="mesh" class="collision" pos="0.15255 0.336 0.0172" quat="0.5 0.5 0.5 -0.5" mesh="j7_e_2_step" material="j7_e_2_step_material"/>
                </body>
                <!-- Link dm_j4310_1_2_step_2 -->
                <body name="dm_j4310_1_2_step_2" pos="0.0343 -0 -0.1205" quat="0.5 -0.5 0.5 -0.5">
                  <!-- Joint from j6_a_3_step to dm_j4310_1_2_step_2 -->
                  <joint axis="0 0 1" name="r_wrist_roll_mimic" type="hinge"/>
                  <inertial pos="0 0 0" mass="1e-09" fullinertia="1e-09 1e-09 1e-09 0 0 0"/>
                  <!-- Part fl6700zz_2_step -->
                  <geom type="mesh" class="visual" pos="0.15255 -0.261 -0.0343" quat="0.5 -0.5 -0.5 -0.5" mesh="fl6700zz_2_step" material="fl6700zz_2_step_material"/>
                  <geom type="mesh" class="collision" pos="0.15255 -0.261 -0.0343" quat="0.5 -0.5 -0.5 -0.5" mesh="fl6700zz_2_step" material="fl6700zz_2_step_material"/>
                  <!-- Part dm_j4310_1_2_step_2 -->
                  <geom type="mesh" class="visual" pos="-0.15255 0.261 -0.0343" quat="0.5 0.5 -0.5 0.5" mesh="dm_j4310_1_2_step_2" material="dm_j4310_1_2_step_2_material"/>
                  <geom type="mesh" class="collision" pos="-0.15255 0.261 -0.0343" quat="0.5 0.5 -0.5 0.5" mesh="dm_j4310_1_2_step_2" material="dm_j4310_1_2_step_2_material"/>
                  <!-- Part j7_b_2_step -->
                  <geom type="mesh" class="visual" pos="-0.15255 -0.261 -0.0343" quat="0.5 -0.5 0.5 0.5" mesh="j7_b_2_step" material="j7_b_2_step_material"/>
                  <geom type="mesh" class="collision" pos="-0.15255 -0.261 -0.0343" quat="0.5 -0.5 0.5 0.5" mesh="j7_b_2_step" material="j7_b_2_step_material"/>
                  <!-- Part j7_a_2_step -->
                  <geom type="mesh" class="visual" pos="-0.15255 0.261 -0.0343" quat="0.5 0.5 -0.5 0.5" mesh="j7_a_2_step" material="j7_a_2_step_material"/>
                  <geom type="mesh" class="collision" pos="-0.15255 0.261 -0.0343" quat="0.5 0.5 -0.5 0.5" mesh="j7_a_2_step" material="j7_a_2_step_material"/>
                  <!-- Part j7_c_2_step -->
                  <geom type="mesh" class="visual" pos="-0.15255 0.261 -0.0343" quat="0.5 0.5 -0.5 0.5" mesh="j7_c_2_step" material="j7_c_2_step_material"/>
                  <geom type="mesh" class="collision" pos="-0.15255 0.261 -0.0343" quat="0.5 0.5 -0.5 0.5" mesh="j7_c_2_step" material="j7_c_2_step_material"/>
                  <!-- Part fl6700zz_2_step_1 -->
                  <geom type="mesh" class="visual" pos="0.15255 -0.261 -0.0343" quat="0.5 -0.5 -0.5 -0.5" mesh="fl6700zz_2_step_1" material="fl6700zz_2_step_1_material"/>
                  <geom type="mesh" class="collision" pos="0.15255 -0.261 -0.0343" quat="0.5 -0.5 -0.5 -0.5" mesh="fl6700zz_2_step_1" material="fl6700zz_2_step_1_material"/>
                  <!-- Part j7_b_2_step_2 -->
                  <geom type="mesh" class="visual" pos="-0.15245 0.261 -0.0343" quat="0.5 0.5 0.5 -0.5" mesh="j7_b_2_step_2" material="j7_b_2_step_2_material"/>
                  <geom type="mesh" class="collision" pos="-0.15245 0.261 -0.0343" quat="0.5 0.5 0.5 -0.5" mesh="j7_b_2_step_2" material="j7_b_2_step_2_material"/>
                  <!-- Link gripper_base -->
                  <body name="gripper_base" pos="0.0205 -0 -0.0343" quat="0.707107 0 -0.707107 -0">
                    <!-- Joint from dm_j4310_1_2_step_2 to gripper_base -->
                    <joint axis="0 0 1" name="r_wrist_pitch" type="hinge" range="-1.5707963267948966 1.5707963267948966"/>
                    <inertial pos="0.000529526 0.0844612 0.015076" mass="0.213224" fullinertia="0.000384882 0.000313838 0.0001816 6.86913e-07 3.22364e-06 -2.49811e-05"/>
                    <!-- Part feetech_sts3215__configuration_default -->
                    <geom type="mesh" class="visual" pos="0.00939992 0.0819874 -0.0103343" quat="0.704416 -0.0616311 -0.0616311 -0.704416" mesh="feetech_sts3215__configuration_default" material="feetech_sts3215__configuration_default_material"/>
                    <geom type="mesh" class="collision" pos="0.00939992 0.0819874 -0.0103343" quat="0.704416 -0.0616311 -0.0616311 -0.704416" mesh="feetech_sts3215__configuration_default" material="feetech_sts3215__configuration_default_material"/>
                    <!-- Part j8_b_2_step -->
                    <geom type="mesh" class="visual" pos="-9.99999e-07 0.260999 0.17305" quat="0.707107 0.707107 -0 -0" mesh="j8_b_2_step" material="j8_b_2_step_material"/>
                    <geom type="mesh" class="collision" pos="-9.99999e-07 0.260999 0.17305" quat="0.707107 0.707107 -0 -0" mesh="j8_b_2_step" material="j8_b_2_step_material"/>
                    <!-- Part gripper_base -->
                    <geom type="mesh" class="visual" pos="-0.0252001 0.127739 -0.01538" quat="0.707107 -2.70466e-06 0.707107 -2.70466e-06" mesh="gripper_base" material="gripper_base_material"/>
                    <geom type="mesh" class="collision" pos="-0.0252001 0.127739 -0.01538" quat="0.707107 -2.70466e-06 0.707107 -2.70466e-06" mesh="gripper_base" material="gripper_base_material"/>
                    <!-- Part b0404 -->
                    <geom type="mesh" class="visual" pos="0.0687999 0.0535004 0.0260817" quat="0.499998 -0.500002 0.500002 0.499998" mesh="b0404" material="b0404_material"/>
                    <geom type="mesh" class="collision" pos="0.0687999 0.0535004 0.0260817" quat="0.499998 -0.500002 0.500002 0.499998" mesh="b0404" material="b0404_material"/>
                    <!-- Part camera_imu_support -->
                    <geom type="mesh" class="visual" pos="0.0247999 0.122827 -0.00431896" quat="0.707107 -2.70466e-06 0.707107 -2.70466e-06" mesh="camera_imu_support" material="camera_imu_support_material"/>
                    <geom type="mesh" class="collision" pos="0.0247999 0.122827 -0.00431896" quat="0.707107 -2.70466e-06 0.707107 -2.70466e-06" mesh="camera_imu_support" material="camera_imu_support_material"/>
                    <!-- Part j8_a_2_step -->
                    <geom type="mesh" class="visual" pos="1e-12 0.261 0.17305" quat="0.707107 0.707107 0 -0" mesh="j8_a_2_step" material="j8_a_2_step_material"/>
                    <geom type="mesh" class="collision" pos="1e-12 0.261 0.17305" quat="0.707107 0.707107 0 -0" mesh="j8_a_2_step" material="j8_a_2_step_material"/>
                    <!-- Part backplate -->
                    <geom type="mesh" class="visual" pos="-0.0250001 0.127739 -0.01538" quat="0.707107 -2.70466e-06 0.707107 -2.70466e-06" mesh="backplate" material="backplate_material"/>
                    <geom type="mesh" class="collision" pos="-0.0250001 0.127739 -0.01538" quat="0.707107 -2.70466e-06 0.707107 -2.70466e-06" mesh="backplate" material="backplate_material"/>
                    <!-- Frame openarm_fix -->
                    <site group="3" name="openarm_fix" pos="-0 0.0495 0.0205" quat="0.5 0.5 0.5 -0.5"/>
                    <!-- Frame camera -->
                    <site group="3" name="camera" pos="0.0687999 0.0662004 0.0260816" quat="0.499998 -0.500002 0.500002 0.499998"/>
                    <!-- Link feetech_sts3215__configuration_default -->
                    <body name="feetech_sts3215__configuration_default" pos="0.0177499 0.1071 -0.0147625" quat="0.0616284 0.704416 -0.0616284 -0.704416">
                      <!-- Joint from gripper_base to feetech_sts3215__configuration_default -->
                      <joint axis="0 0 1" name="proximal" type="hinge" range="-1.5707886768702002 7.649924696373489e-06"/>
                      <inertial pos="0.0182592 -0.0259026 0.0175524" mass="0.101487" fullinertia="5.99713e-05 4.50716e-05 3.99848e-05 6.78604e-06 -4.30903e-07 1.10027e-06"/>
                      <!-- Part proximal_side -->
                      <geom type="mesh" class="visual" pos="-0.00297594 -0.0204326 0.0435" quat="0 -0.996195 0.0871557 0" mesh="proximal_side" material="proximal_side_material"/>
                      <geom type="mesh" class="collision" pos="-0.00297594 -0.0204326 0.0435" quat="0 -0.996195 0.0871557 0" mesh="proximal_side" material="proximal_side_material"/>
                      <!-- Part proximal_bottom -->
                      <geom type="mesh" class="visual" pos="-0.00297594 -0.0204326 0.0435" quat="0 -0.996195 0.0871557 0" mesh="proximal_bottom" material="proximal_bottom_material"/>
                      <geom type="mesh" class="collision" pos="-0.00297594 -0.0204326 0.0435" quat="0 -0.996195 0.0871557 0" mesh="proximal_bottom" material="proximal_bottom_material"/>
                      <!-- Part feetech_sts3215__configuration_default_2 -->
                      <geom type="mesh" class="visual" pos="0.0122498 -0.0212176 0.0089" quat="0.353553 -0.353553 -0.612372 0.612372" mesh="feetech_sts3215__configuration_default" material="feetech_sts3215__configuration_default_material"/>
                      <geom type="mesh" class="collision" pos="0.0122498 -0.0212176 0.0089" quat="0.353553 -0.353553 -0.612372 0.612372" mesh="feetech_sts3215__configuration_default" material="feetech_sts3215__configuration_default_material"/>
                      <!-- Part proximal_top -->
                      <geom type="mesh" class="visual" pos="-0.00297594 -0.0204326 0.0435" quat="0 -0.996195 0.0871557 -0" mesh="proximal_top" material="proximal_top_material"/>
                      <geom type="mesh" class="collision" pos="-0.00297594 -0.0204326 0.0435" quat="0 -0.996195 0.0871557 -0" mesh="proximal_top" material="proximal_top_material"/>
                      <!-- Link distal -->
                      <body name="distal" pos="0.0249998 -0.0433013 -0.00055" quat="0.5 0 0 0.866025">
                        <!-- Joint from feetech_sts3215__configuration_default to distal -->
                        <joint axis="0 0 1" name="distal" type="hinge" range="-2.0943951023931953 0.0"/>
                        <inertial pos="-0.0288978 0.00403421 0.0180018" mass="0.0471678" fullinertia="1.19203e-05 1.88956e-05 1.16157e-05 2.06538e-06 3.61884e-07 1.38375e-07"/>
                        <!-- Part distal -->
                        <geom type="mesh" class="visual" pos="0.0337928 0.0127932 0.0435" quat="0 0.422618 -0.906308 0" mesh="distal" material="distal_material"/>
                        <geom type="mesh" class="collision" pos="0.0337928 0.0127932 0.0435" quat="0 0.422618 -0.906308 0" mesh="distal" material="distal_material"/>
                      </body>
                    </body>
                  </body>
                </body>
              </body>
            </body>
          </body>
        </body>
      </body>
    </body>
  </worldbody>
  <asset>
    <mesh file="b0404.stl"/>
    <mesh file="j6_d_3_step.stl"/>
    <mesh file="camera_imu_support.stl"/>
    <mesh file="j5_a_3_step.stl"/>
    <mesh file="j7_b_2_step.stl"/>
    <mesh file="proximal_side.stl"/>
    <mesh file="j1_e_1_step.stl"/>
    <mesh file="j4_b_2_step.stl"/>
    <mesh file="j2_b_2_step.stl"/>
    <mesh file="j1_b_2_step.stl"/>
    <mesh file="j7_e_2_step.stl"/>
    <mesh file="fl6700zz_2_step.stl"/>
    <mesh file="hfsb6_6060_750_1_step.stl"/>
    <mesh file="backplate.stl"/>
    <mesh file="dm_j4310_1_2_step.stl"/>
    <mesh file="proximal_top.stl"/>
    <mesh file="j4_a_2_step.stl"/>
    <mesh file="j8_a_2_step.stl"/>
    <mesh file="j7_a_2_step.stl"/>
    <mesh file="j4_c_2_step.stl"/>
    <mesh file="distal.stl"/>
    <mesh file="j1_c_1_step.stl"/>
    <mesh file="j6_a_3_step.stl"/>
    <mesh file="j6_c_right_2_step.stl"/>
    <mesh file="j2_c_2_step.stl"/>
    <mesh file="j7_b_2_step_2.stl"/>
    <mesh file="j8_b_2_step.stl"/>
    <mesh file="j7_c_2_step.stl"/>
    <mesh file="fl6700zz_2_step_1.stl"/>
    <mesh file="proximal_bottom.stl"/>
    <mesh file="gripper_base.stl"/>
    <mesh file="feetech_sts3215__configuration_default.stl"/>
    <mesh file="j6_b_3_step.stl"/>
    <mesh file="dm_j4310_1_2_step_1.stl"/>
    <mesh file="j2_a_1_step.stl"/>
    <mesh file="dm_j8009p_2_step.stl"/>
    <mesh file="dm_j4310_1_2_step_2.stl"/>
    <mesh file="j4_e_2_step.stl"/>
    <mesh file="dm_j8009p_2_step_1.stl"/>
    <mesh file="j4_d_2_step.stl"/>
    <mesh file="fl6803zz_2_step.stl"/>
    <mesh file="dm_j4340_2_step.stl"/>
    <mesh file="j1_d_1_step.stl"/>
    <mesh file="j1_a_1_step.stl"/>
    <mesh file="dm_j4340p_2_step.stl"/>
    <material name="j1_b_2_step_material" rgba="0.792157 0.819608 0.933333 1"/>
    <material name="hfsb6_6060_750_1_step_material" rgba="0.792157 0.819608 0.933333 1"/>
    <material name="dm_j8009p_2_step_material" rgba="0.792157 0.819608 0.933333 1"/>
    <material name="j1_a_1_step_material" rgba="0.792157 0.819608 0.933333 1"/>
    <material name="dm_j8009p_2_step_1_material" rgba="0.792157 0.819608 0.933333 1"/>
    <material name="j1_e_1_step_material" rgba="0.792157 0.819608 0.933333 1"/>
    <material name="j1_d_1_step_material" rgba="0.792157 0.819608 0.933333 1"/>
    <material name="j1_c_1_step_material" rgba="0.792157 0.819608 0.933333 1"/>
    <material name="j2_a_1_step_material" rgba="0.792157 0.819608 0.933333 1"/>
    <material name="j2_c_2_step_material" rgba="0.792157 0.819608 0.933333 1"/>
    <material name="j2_b_2_step_material" rgba="0.792157 0.819608 0.933333 1"/>
    <material name="dm_j4340p_2_step_material" rgba="0.792157 0.819608 0.933333 1"/>
    <material name="fl6803zz_2_step_material" rgba="0.792157 0.819608 0.933333 1"/>
    <material name="j4_a_2_step_material" rgba="0.792157 0.819608 0.933333 1"/>
    <material name="dm_j4340_2_step_material" rgba="0.792157 0.819608 0.933333 1"/>
    <material name="j4_b_2_step_material" rgba="0.792157 0.819608 0.933333 1"/>
    <material name="j4_d_2_step_material" rgba="0.792157 0.819608 0.933333 1"/>
    <material name="j4_c_2_step_material" rgba="0.792157 0.819608 0.933333 1"/>
    <material name="dm_j4310_1_2_step_material" rgba="0.792157 0.819608 0.933333 1"/>
    <material name="j4_e_2_step_material" rgba="0.792157 0.819608 0.933333 1"/>
    <material name="j6_d_3_step_material" rgba="0.792157 0.819608 0.933333 1"/>
    <material name="dm_j4310_1_2_step_1_material" rgba="0.792157 0.819608 0.933333 1"/>
    <material name="j6_b_3_step_material" rgba="0.792157 0.819608 0.933333 1"/>
    <material name="j5_a_3_step_material" rgba="0.792157 0.819608 0.933333 1"/>
    <material name="j6_a_3_step_material" rgba="0.792157 0.819608 0.933333 1"/>
    <material name="j6_c_right_2_step_material" rgba="0.792157 0.819608 0.933333 1"/>
    <material name="j7_e_2_step_material" rgba="0.792157 0.819608 0.933333 1"/>
    <material name="fl6700zz_2_step_material" rgba="0.792157 0.819608 0.933333 1"/>
    <material name="dm_j4310_1_2_step_2_material" rgba="0.792157 0.819608 0.933333 1"/>
    <material name="j7_b_2_step_material" rgba="0.792157 0.819608 0.933333 1"/>
    <material name="j7_a_2_step_material" rgba="0.792157 0.819608 0.933333 1"/>
    <material name="j7_c_2_step_material" rgba="0.792157 0.819608 0.933333 1"/>
    <material name="fl6700zz_2_step_1_material" rgba="0.792157 0.819608 0.933333 1"/>
    <material name="j7_b_2_step_2_material" rgba="0.792157 0.819608 0.933333 1"/>
    <material name="feetech_sts3215__configuration_default_material" rgba="0.647059 0.647059 0.647059 1"/>
    <material name="j8_b_2_step_material" rgba="0.792157 0.819608 0.933333 1"/>
    <material name="gripper_base_material" rgba="0.615686 0.811765 0.929412 1"/>
    <material name="b0404_material" rgba="0.372549 0.654902 0.239216 1"/>
    <material name="camera_imu_support_material" rgba="0.615686 0.811765 0.929412 1"/>
    <material name="j8_a_2_step_material" rgba="0.792157 0.819608 0.933333 1"/>
    <material name="backplate_material" rgba="0.917647 0.917647 0.917647 1"/>
    <material name="proximal_side_material" rgba="0.647059 0.647059 0.647059 1"/>
    <material name="proximal_bottom_material" rgba="0.647059 0.647059 0.647059 1"/>
    <material name="proximal_top_material" rgba="0.647059 0.647059 0.647059 1"/>
    <material name="distal_material" rgba="0.231373 0.380392 0.705882 1"/>
  </asset>
  <actuator>
    <position class="openarm_right" name="r_arm_pitch" joint="r_arm_pitch" inheritrange="1"/>
    <position class="openarm_right" name="r_arm_roll" joint="r_arm_roll" inheritrange="1"/>
    <position class="openarm_right" name="r_arm_yaw" joint="r_arm_yaw" inheritrange="1"/>
    <position class="openarm_right" name="r_elbow" joint="r_elbow" inheritrange="1"/>
    <position class="openarm_right" name="r_wrist_yaw" joint="r_wrist_yaw" inheritrange="1"/>
    <position class="openarm_right" name="r_wrist_roll" joint="r_wrist_roll" inheritrange="1"/>
    <position class="openarm_right" name="r_wrist_pitch" joint="r_wrist_pitch" inheritrange="1"/>
    <position class="openarm_right" name="proximal" joint="proximal" inheritrange="1"/>
    <position class="openarm_right" name="distal" joint="distal" inheritrange="1"/>
  </actuator>
  <equality>
    <joint joint1="r_wrist_roll_mimic" joint2="r_wrist_roll" polycoef="0 -1.0 0 0 0"/>
  </equality>
</mujoco>
